<?xml version="1.0" ?>
<!-- =================================================================================== -->
<!-- |    This document was autogenerated by xacro from j1n6srobotiq_integration.xacro | -->
<!-- |    EDITING THIS FILE BY HAND IS NOT RECOMMENDED                                 | -->
<!-- =================================================================================== -->
<!-- j1n6srobotiq refers to jaco v1 6DOF non-spherical with robotiq gripper -->
<robot name="j1n6srobotiq" xmlns:body="http://playerstage.sourceforge.net/gazebo/xmlschema/#body" xmlns:controller="http://playerstage.sourceforge.net/gazebo/xmlschema/#controller" xmlns:gazebo="http://playerstage.sourceforge.net/gazebo/xmlschema/#gz" xmlns:geom="http://playerstage.sourceforge.net/gazebo/xmlschema/#geom" xmlns:interface="http://playerstage.sourceforge.net/gazebo/xmlschema/#interface" xmlns:joint="http://playerstage.sourceforge.net/gazebo/xmlschema/#joint" xmlns:model="http://playerstage.sourceforge.net/gazebo/xmlschema/#model" xmlns:physics="http://playerstage.sourceforge.net/gazebo/xmlschema/#physics" xmlns:renderable="http://playerstage.sourceforge.net/gazebo/xmlschema/#renderable" xmlns:rendering="http://playerstage.sourceforge.net/gazebo/xmlschema/#rendering" xmlns:sensor="http://playerstage.sourceforge.net/gazebo/xmlschema/#sensor" xmlns:xi="http://www.w3.org/2001/XInclude">
  <!-- links      		mesh_no
   base           		0
   shoulder       		1
   arm            		2
   forearm        		3
   wrist          		4
   arm_mico       		5
   arm_half1 (7dof)		6
   arm_half2 (7dof)		7
   wrist_spherical_1  8
   wrist_spherical_2  9

   hand 3 finger  		55
   hand_2finger   		56
   finger_proximal		57
   finger_distal      58
-->
  <!-- links      		mesh_no
   base           		0
   shoulder       		1
   arm            		2
   forearm        		3
   wrist          		4
   arm_mico       		5
   arm_half1 (7dof)		6
   arm_half2 (7dof)		7
   wrist_spherical_1  8
   wrist_spherical_2  9

   hand 3 finger  		55
   hand_2finger   		56
   finger_proximal		57
   finger_distal      58
-->
  <link name="base_link"/>
  <!-- ros_control plugin -->
  <gazebo>
    <plugin filename="libgazebo_ros_control.so" name="gazebo_ros_control">
      <robotNamespace>j1n6s300</robotNamespace>
      <robotSimType>gazebo_ros_control/DefaultRobotHWSim</robotSimType>
      <legacyModeNS>true</legacyModeNS>
    </plugin>
  </gazebo>
  <link name="j1n6s300_link_base">
    <visual>
      <geometry>
        <mesh filename="package://kinova_description/meshes/base.dae"/>
      </geometry>
      <material name="carbon_fiber">
        <color rgba="0.792156862745098 0.819607843137255 0.933333333333333 1"/>
      </material>
    </visual>
    <collision>
      <origin rpy="0 0 0" xyz="0 0 0.078375"/>
      <geometry>
        <cylinder length="0.15675" radius="0.04125"/>
      </geometry>
    </collision>
    <inertial>
      <mass value="0.46784"/>
      <origin rpy="0 0 0" xyz="0 0 0.1255"/>
      <inertia ixx="0.000951270861568" ixy="0" ixz="0" iyy="0.000951270861568" iyz="0" izz="0.00037427200000000004"/>
    </inertial>
  </link>
  <joint name="j1n6s300_joint_base" type="fixed">
    <parent link="base_link"/>
    <child link="j1n6s300_link_base"/>
    <axis xyz="0 0 0"/>
    <origin rpy="0 0 0" xyz="0 0 0"/>
    <dynamics damping="0.0" friction="0.0"/>
  </joint>
  <link name="j1n6s300_link_1">
    <visual>
      <geometry>
        <mesh filename="package://kinova_description/meshes/shoulder.dae"/>
      </geometry>
      <material name="carbon_fiber">
        <color rgba="0.792156862745098 0.819607843137255 0.933333333333333 1"/>
      </material>
    </visual>
    <visual>
      <geometry>
        <mesh filename="package://kinova_description/meshes/ring_big.dae"/>
      </geometry>
    </visual>
    <collision>
      <origin rpy="0 0 0" xyz="0 0 -0.0187"/>
      <geometry>
        <cylinder length="0.0374" radius="0.041"/>
      </geometry>
    </collision>
    <collision>
      <origin rpy="0 0 0" xyz="0 -0.0205 -0.07994"/>
      <geometry>
        <box size="0.082 0.041 0.08488"/>
      </geometry>
    </collision>
    <collision>
      <origin rpy="1.5707963267948966 0 0" xyz="0 -0.0205 -0.119"/>
      <geometry>
        <cylinder length="0.041" radius="0.041"/>
      </geometry>
    </collision>
    <inertial>
      <mass value="0.7477"/>
      <origin xyz="0 -0.002 -0.0605"/>
      <inertia ixx="0.0015203172520400004" ixy="0" ixz="0" iyy="0.0015203172520400004" iyz="0" izz="0.00059816"/>
    </inertial>
  </link>
  <joint name="j1n6s300_joint_1" type="revolute">
    <parent link="j1n6s300_link_base"/>
    <child link="j1n6s300_link_1"/>
    <axis xyz="0 0 1"/>
    <limit effort="40" lower="-3.141592653589793" upper="3.141592653589793" velocity="0.6283185307179586"/>
    <origin rpy="0 3.141592653589793 0" xyz="0 0 0.15675"/>
    <dynamics damping="0.0" friction="0.0"/>
  </joint>
  <transmission name="j1n6s300_joint_1_trans">
    <type>transmission_interface/SimpleTransmission</type>
    <joint name="j1n6s300_joint_1">
      <hardwareInterface>hardware_interface/EffortJointInterface</hardwareInterface>
    </joint>
    <actuator name="j1n6s300_joint_1_actuator">
      <hardwareInterface>hardware_interface/EffortJointInterface</hardwareInterface>
      <mechanicalReduction>160</mechanicalReduction>
    </actuator>
  </transmission>
  <!--For torque sensing in simulation-->
  <gazebo reference="j1n6s300_joint_1">
    <implicitSpringDamper>1</implicitSpringDamper>
    <provideFeedback>true</provideFeedback>
  </gazebo>
  <gazebo>
    <plugin filename="libgazebo_ros_ft_sensor.so" name="ft_sensor">
      <updateRate>30.0</updateRate>
      <topicName>j1n6s300_joint_1_ft_sensor_topic</topicName>
      <jointName>j1n6s300_joint_1</jointName>
    </plugin>
  </gazebo>
  <link name="j1n6s300_joint_1_rotor_inertia">
    <inertial>
      <!-- The actuator modules weigh 570g and 357g respectively. We guess how much rotor + gearbox are -->
      <mass value="1e-2"/>
      <!-- Arbitrarily low mass -->
      <origin rpy="0 0 0" xyz="0 0 0"/>
      <inertia ixx="0" ixy="0" ixz="0" iyy="0" iyz="0" izz="0.092672"/>
    </inertial>
  </link>
  <joint name="j1n6s300_joint_1_rotor_inertia_joint" type="fixed">
    <axis xyz="0 0 1"/>
    <parent link="j1n6s300_link_1"/>
    <child link="j1n6s300_joint_1_rotor_inertia"/>
  </joint>
  <link name="j1n6s300_link_2">
    <visual>
      <geometry>
        <mesh filename="package://kinova_description/meshes/arm.dae"/>
      </geometry>
      <material name="carbon_fiber">
        <color rgba="0.792156862745098 0.819607843137255 0.933333333333333 1"/>
      </material>
    </visual>
    <visual>
      <geometry>
        <mesh filename="package://kinova_description/meshes/ring_big.dae"/>
      </geometry>
    </visual>
    <collision>
      <origin rpy="0 0 0" xyz="0 0 -0.0215"/>
      <geometry>
        <cylinder length="0.043" radius="0.0415"/>
      </geometry>
    </collision>
    <collision>
      <origin rpy="0 0 0" xyz="0 -0.204875 -0.0325"/>
      <geometry>
        <box size="0.0825 0.40975 0.0215"/>
      </geometry>
    </collision>
    <collision>
      <origin rpy="0 0 0" xyz="0 -0.204875 -0.0215"/>
      <geometry>
        <box size="0.0825 0.26975 0.0325"/>
      </geometry>
    </collision>
    <collision>
      <origin rpy="0 0 0" xyz="0 -0.40975 -0.0215"/>
      <geometry>
        <cylinder length="0.043" radius="0.0415"/>
      </geometry>
    </collision>
    <inertial>
      <mass value="0.99"/>
      <origin xyz="0 -0.2065 -0.01"/>
      <inertia ixx="0.010502207990999999" ixy="0" ixz="0" iyy="0.0007920000000000001" iyz="0" izz="0.010502207990999999"/>
    </inertial>
  </link>
  <joint name="j1n6s300_joint_2" type="revolute">
    <parent link="j1n6s300_link_1"/>
    <child link="j1n6s300_link_2"/>
    <axis xyz="0 0 1"/>
    <limit effort="80" lower="0.8203047484373349" upper="5.462880558742252" velocity="0.6283185307179586"/>
    <origin rpy="-1.5707963267948966 0 3.141592653589793" xyz="0 0.0016 -0.11875"/>
    <dynamics damping="0.0" friction="0.0"/>
  </joint>
  <transmission name="j1n6s300_joint_2_trans">
    <type>transmission_interface/SimpleTransmission</type>
    <joint name="j1n6s300_joint_2">
      <hardwareInterface>hardware_interface/EffortJointInterface</hardwareInterface>
    </joint>
    <actuator name="j1n6s300_joint_2_actuator">
      <hardwareInterface>hardware_interface/EffortJointInterface</hardwareInterface>
      <mechanicalReduction>160</mechanicalReduction>
    </actuator>
  </transmission>
  <!--For torque sensing in simulation-->
  <gazebo reference="j1n6s300_joint_2">
    <implicitSpringDamper>1</implicitSpringDamper>
    <provideFeedback>true</provideFeedback>
  </gazebo>
  <gazebo>
    <plugin filename="libgazebo_ros_ft_sensor.so" name="ft_sensor">
      <updateRate>30.0</updateRate>
      <topicName>j1n6s300_joint_2_ft_sensor_topic</topicName>
      <jointName>j1n6s300_joint_2</jointName>
    </plugin>
  </gazebo>
  <link name="j1n6s300_joint_2_rotor_inertia">
    <inertial>
      <!-- The actuator modules weigh 570g and 357g respectively. We guess how much rotor + gearbox are -->
      <mass value="1e-2"/>
      <!-- Arbitrarily low mass -->
      <origin rpy="0 0 0" xyz="0 0 0"/>
      <inertia ixx="0" ixy="0" ixz="0" iyy="0" iyz="0" izz="0.092672"/>
    </inertial>
  </link>
  <joint name="j1n6s300_joint_2_rotor_inertia_joint" type="fixed">
    <axis xyz="0 0 1"/>
    <parent link="j1n6s300_link_2"/>
    <child link="j1n6s300_joint_2_rotor_inertia"/>
  </joint>
  <link name="j1n6s300_link_3">
    <visual>
      <geometry>
        <mesh filename="package://kinova_description/meshes/forearm.dae"/>
      </geometry>
      <material name="carbon_fiber">
        <color rgba="0.792156862745098 0.819607843137255 0.933333333333333 1"/>
      </material>
    </visual>
    <visual>
      <geometry>
        <mesh filename="package://kinova_description/meshes/ring_big.dae"/>
      </geometry>
    </visual>
    <collision>
      <origin rpy="0 0 0" xyz="0 0 -0.0215"/>
      <geometry>
        <cylinder length="0.043" radius="0.0415"/>
      </geometry>
    </collision>
    <collision>
      <origin rpy="0 0 0" xyz="0 0.053 -0.0215"/>
      <geometry>
        <box size="0.0825 0.106 0.043"/>
      </geometry>
    </collision>
    <collision>
      <origin rpy="1.5707963267948966 0 0" xyz="0 0.15525 -0.0115"/>
      <geometry>
        <cylinder length="0.1035" radius="0.0315"/>
      </geometry>
    </collision>
    <inertial>
      <mass value="0.6763"/>
      <origin xyz="0 0.081 -0.0086"/>
      <inertia ixx="0.0014202243190800001" ixy="0" ixz="0" iyy="0.000304335" iyz="0" izz="0.0014202243190800001"/>
    </inertial>
  </link>
  <joint name="j1n6s300_joint_3" type="revolute">
    <parent link="j1n6s300_link_2"/>
    <child link="j1n6s300_link_3"/>
    <axis xyz="0 0 1"/>
    <limit effort="40" lower="0.33161255787892263" upper="5.951572749300664" velocity="0.6283185307179586"/>
    <origin rpy="0 3.141592653589793 0" xyz="0 -0.410 0"/>
    <dynamics damping="0.0" friction="0.0"/>
  </joint>
  <transmission name="j1n6s300_joint_3_trans">
    <type>transmission_interface/SimpleTransmission</type>
    <joint name="j1n6s300_joint_3">
      <hardwareInterface>hardware_interface/EffortJointInterface</hardwareInterface>
    </joint>
    <actuator name="j1n6s300_joint_3_actuator">
      <hardwareInterface>hardware_interface/EffortJointInterface</hardwareInterface>
      <mechanicalReduction>160</mechanicalReduction>
    </actuator>
  </transmission>
  <!--For torque sensing in simulation-->
  <gazebo reference="j1n6s300_joint_3">
    <implicitSpringDamper>1</implicitSpringDamper>
    <provideFeedback>true</provideFeedback>
  </gazebo>
  <gazebo>
    <plugin filename="libgazebo_ros_ft_sensor.so" name="ft_sensor">
      <updateRate>30.0</updateRate>
      <topicName>j1n6s300_joint_3_ft_sensor_topic</topicName>
      <jointName>j1n6s300_joint_3</jointName>
    </plugin>
  </gazebo>
  <link name="j1n6s300_joint_3_rotor_inertia">
    <inertial>
      <!-- The actuator modules weigh 570g and 357g respectively. We guess how much rotor + gearbox are -->
      <mass value="1e-2"/>
      <!-- Arbitrarily low mass -->
      <origin rpy="0 0 0" xyz="0 0 0"/>
      <inertia ixx="0" ixy="0" ixz="0" iyy="0" iyz="0" izz="0.092672"/>
    </inertial>
  </link>
  <joint name="j1n6s300_joint_3_rotor_inertia_joint" type="fixed">
    <axis xyz="0 0 1"/>
    <parent link="j1n6s300_link_3"/>
    <child link="j1n6s300_joint_3_rotor_inertia"/>
  </joint>
  <link name="j1n6s300_link_4">
    <visual>
      <geometry>
        <mesh filename="package://kinova_description/meshes/wrist.dae"/>
      </geometry>
      <material name="carbon_fiber">
        <color rgba="0.792156862745098 0.819607843137255 0.933333333333333 1"/>
      </material>
    </visual>
    <visual>
      <geometry>
        <mesh filename="package://kinova_description/meshes/ring_small.dae"/>
      </geometry>
    </visual>
    <collision>
      <origin rpy="0 0 0" xyz="0 0 -0.0125"/>
      <geometry>
        <cylinder length="0.025" radius="0.0315"/>
      </geometry>
    </collision>
    <collision>
      <origin rpy="-1.0471975511965976 0 0" xyz="0 -0.025 -0.055"/>
      <geometry>
        <cylinder length="0.025" radius="0.0315"/>
      </geometry>
    </collision>
    <collision>
      <origin rpy="-0.5235987755982988 0 0" xyz="0 -0.01 -0.0375"/>
      <geometry>
        <cylinder length="0.05" radius="0.0315"/>
      </geometry>
    </collision>
    <inertial>
      <mass value="0.426367"/>
      <origin xyz="0 -0.037 -0.0642"/>
      <inertia ixx="7.734969059999999e-05" ixy="0" ixz="0" iyy="7.734969059999999e-05" iyz="0" izz="0.0001428"/>
    </inertial>
  </link>
  <joint name="j1n6s300_joint_4" type="revolute">
    <parent link="j1n6s300_link_3"/>
    <child link="j1n6s300_link_4"/>
    <axis xyz="0 0 1"/>
    <limit effort="20" lower="-3.141592653589793" upper="3.141592653589793" velocity="0.8377580409572781"/>
    <origin rpy="-1.5707963267948966 0 3.141592653589793" xyz="0 0.2073 -0.0114"/>
    <dynamics damping="0.0" friction="0.0"/>
  </joint>
  <transmission name="j1n6s300_joint_4_trans">
    <type>transmission_interface/SimpleTransmission</type>
    <joint name="j1n6s300_joint_4">
      <hardwareInterface>hardware_interface/EffortJointInterface</hardwareInterface>
    </joint>
    <actuator name="j1n6s300_joint_4_actuator">
      <hardwareInterface>hardware_interface/EffortJointInterface</hardwareInterface>
      <mechanicalReduction>160</mechanicalReduction>
    </actuator>
  </transmission>
  <!--For torque sensing in simulation-->
  <gazebo reference="j1n6s300_joint_4">
    <implicitSpringDamper>1</implicitSpringDamper>
    <provideFeedback>true</provideFeedback>
  </gazebo>
  <gazebo>
    <plugin filename="libgazebo_ros_ft_sensor.so" name="ft_sensor">
      <updateRate>30.0</updateRate>
      <topicName>j1n6s300_joint_4_ft_sensor_topic</topicName>
      <jointName>j1n6s300_joint_4</jointName>
    </plugin>
  </gazebo>
  <link name="j1n6s300_joint_4_rotor_inertia">
    <inertial>
      <!-- The actuator modules weigh 570g and 357g respectively. We guess how much rotor + gearbox are -->
      <mass value="1e-2"/>
      <!-- Arbitrarily low mass -->
      <origin rpy="0 0 0" xyz="0 0 0"/>
      <inertia ixx="0" ixy="0" ixz="0" iyy="0" iyz="0" izz="0.022385000000000002"/>
    </inertial>
  </link>
  <joint name="j1n6s300_joint_4_rotor_inertia_joint" type="fixed">
    <axis xyz="0 0 1"/>
    <parent link="j1n6s300_link_4"/>
    <child link="j1n6s300_joint_4_rotor_inertia"/>
  </joint>
  <link name="j1n6s300_link_5">
    <visual>
      <geometry>
        <mesh filename="package://kinova_description/meshes/wrist.dae"/>
      </geometry>
      <material name="carbon_fiber">
        <color rgba="0.792156862745098 0.819607843137255 0.933333333333333 1"/>
      </material>
    </visual>
    <visual>
      <geometry>
        <mesh filename="package://kinova_description/meshes/ring_small.dae"/>
      </geometry>
    </visual>
    <collision>
      <origin rpy="0 0 0" xyz="0 0 -0.0125"/>
      <geometry>
        <cylinder length="0.025" radius="0.0315"/>
      </geometry>
    </collision>
    <collision>
      <origin rpy="-1.0471975511965976 0 0" xyz="0 -0.025 -0.055"/>
      <geometry>
        <cylinder length="0.025" radius="0.0315"/>
      </geometry>
    </collision>
    <collision>
      <origin rpy="-0.5235987755982988 0 0" xyz="0 -0.01 -0.0375"/>
      <geometry>
        <cylinder length="0.05" radius="0.0315"/>
      </geometry>
    </collision>
    <inertial>
      <mass value="0.426367"/>
      <origin xyz="0 -0.037 -0.0642"/>
      <inertia ixx="7.734969059999999e-05" ixy="0" ixz="0" iyy="7.734969059999999e-05" iyz="0" izz="0.0001428"/>
    </inertial>
  </link>
  <joint name="j1n6s300_joint_5" type="revolute">
    <parent link="j1n6s300_link_4"/>
    <child link="j1n6s300_link_5"/>
    <axis xyz="0 0 1"/>
    <limit effort="20" lower="-3.141592653589793" upper="3.141592653589793" velocity="0.8377580409572781"/>
    <origin rpy="1.0471975511965976 0 3.141592653589793" xyz="0 -0.03703 -0.06414"/>
    <dynamics damping="0.0" friction="0.0"/>
  </joint>
  <transmission name="j1n6s300_joint_5_trans">
    <type>transmission_interface/SimpleTransmission</type>
    <joint name="j1n6s300_joint_5">
      <hardwareInterface>hardware_interface/EffortJointInterface</hardwareInterface>
    </joint>
    <actuator name="j1n6s300_joint_5_actuator">
      <hardwareInterface>hardware_interface/EffortJointInterface</hardwareInterface>
      <mechanicalReduction>160</mechanicalReduction>
    </actuator>
  </transmission>
  <!--For torque sensing in simulation-->
  <gazebo reference="j1n6s300_joint_5">
    <implicitSpringDamper>1</implicitSpringDamper>
    <provideFeedback>true</provideFeedback>
  </gazebo>
  <gazebo>
    <plugin filename="libgazebo_ros_ft_sensor.so" name="ft_sensor">
      <updateRate>30.0</updateRate>
      <topicName>j1n6s300_joint_5_ft_sensor_topic</topicName>
      <jointName>j1n6s300_joint_5</jointName>
    </plugin>
  </gazebo>
  <link name="j1n6s300_joint_5_rotor_inertia">
    <inertial>
      <!-- The actuator modules weigh 570g and 357g respectively. We guess how much rotor + gearbox are -->
      <mass value="1e-2"/>
      <!-- Arbitrarily low mass -->
      <origin rpy="0 0 0" xyz="0 0 0"/>
      <inertia ixx="0" ixy="0" ixz="0" iyy="0" iyz="0" izz="0.022385000000000002"/>
    </inertial>
  </link>
  <joint name="j1n6s300_joint_5_rotor_inertia_joint" type="fixed">
    <axis xyz="0 0 1"/>
    <parent link="j1n6s300_link_5"/>
    <child link="j1n6s300_joint_5_rotor_inertia"/>
  </joint>
  <link name="j1n6s300_link_6">
    <visual>
      <geometry>
        <mesh filename="package://kinova_description/meshes/ring_small.dae"/>
      </geometry>
    </visual>
    <inertial>
      <mass value="0.99"/>
      <origin xyz="0 0 -0.06"/>
      <inertia ixx="0.00034532361869999995" ixy="0" ixz="0" iyy="0.00034532361869999995" iyz="0" izz="0.0005815999999999999"/>
    </inertial>
  </link>
  <joint name="j1n6s300_joint_6" type="revolute">
    <parent link="j1n6s300_link_5"/>
    <child link="j1n6s300_link_6"/>
    <axis xyz="0 0 1"/>
    <limit effort="20" lower="-3.141592653589793" upper="3.141592653589793" velocity="0.8377580409572781"/>
    <origin rpy="1.0471975511965976 0 3.141592653589793" xyz="0 -0.03703 -0.06414"/>
    <dynamics damping="0.0" friction="0.0"/>
  </joint>
  <transmission name="j1n6s300_joint_6_trans">
    <type>transmission_interface/SimpleTransmission</type>
    <joint name="j1n6s300_joint_6">
      <hardwareInterface>hardware_interface/EffortJointInterface</hardwareInterface>
    </joint>
    <actuator name="j1n6s300_joint_6_actuator">
      <hardwareInterface>hardware_interface/EffortJointInterface</hardwareInterface>
      <mechanicalReduction>160</mechanicalReduction>
    </actuator>
  </transmission>
  <!--For torque sensing in simulation-->
  <gazebo reference="j1n6s300_joint_6">
    <implicitSpringDamper>1</implicitSpringDamper>
    <provideFeedback>true</provideFeedback>
  </gazebo>
  <gazebo>
    <plugin filename="libgazebo_ros_ft_sensor.so" name="ft_sensor">
      <updateRate>30.0</updateRate>
      <topicName>j1n6s300_joint_6_ft_sensor_topic</topicName>
      <jointName>j1n6s300_joint_6</jointName>
    </plugin>
  </gazebo>
  <link name="j1n6s300_joint_6_rotor_inertia">
    <inertial>
      <!-- The actuator modules weigh 570g and 357g respectively. We guess how much rotor + gearbox are -->
      <mass value="1e-2"/>
      <!-- Arbitrarily low mass -->
      <origin rpy="0 0 0" xyz="0 0 0"/>
      <inertia ixx="0" ixy="0" ixz="0" iyy="0" iyz="0" izz="0.022385000000000002"/>
    </inertial>
  </link>
  <joint name="j1n6s300_joint_6_rotor_inertia_joint" type="fixed">
    <axis xyz="0 0 1"/>
    <parent link="j1n6s300_link_6"/>
    <child link="j1n6s300_joint_6_rotor_inertia"/>
  </joint>
  <link name="j1n6s300_end_effector"/>
  <joint name="j1n6s300_joint_end_effector" type="fixed">
    <parent link="j1n6s300_link_6"/>
    <child link="j1n6s300_end_effector"/>
    <axis xyz="0 0 0"/>
    <origin rpy="3.141592653589793 0 1.0471975511965979" xyz="0 0 -0.28"/>
  </joint>
  <link name="Adapter_Sleeve_Robotiq">
    <visual>
      <!-- Approximate -->
      <origin rpy="1.5707963267948966 0 0" xyz="-0.0315 0.0315 -0.046"/>
      <geometry>
        <mesh filename="package://kinova_description/meshes/Adapter_Sleeve_Robotiq.STL" scale="0.001 0.001 0.001"/>
      </geometry>
      <material name="aluminium">
        <color rgba="0.5333333333333333 0.5450980392156862 0.5529411764705883 1"/>
      </material>
    </visual>
    <collision>
      <origin rpy="0 0 0" xyz="0 0 -0.0315"/>
      <geometry>
        <cylinder length="0.063" radius="0.0315"/>
      </geometry>
    </collision>
  </link>
  <joint name="link6_to_adapter_sleeve" type="fixed">
    <!-- we have some unknown rotational offset... -->
    <origin rpy="0 0 -0.5235987755982988" xyz="0 0 0"/>
    <parent link="j1n6s300_link_6"/>
    <child link="Adapter_Sleeve_Robotiq"/>
  </joint>
  <!-- mount the fts to the robot -->
  <joint name="ft300_fix" type="fixed">
    <origin rpy="3.141592653589793 0 -1.5707963267948966" xyz="0 0 -0.041"/>
    <parent link="Adapter_Sleeve_Robotiq"/>
    <child link="ft300_mounting_plate"/>
  </joint>
  <!-- Link representing the FT300 force-torque sensor -->
  <link name="ft300_sensor">
    <inertial>
      <origin rpy="0 0 0" xyz="0 0 -0.017"/>
      <mass value="0.300"/>
      <inertia ixx="0.000262" ixy="0" ixz="1e-06" iyx="0" iyy="0.000265" iyz="1e-06" izx="-1e-06" izy="1e-06" izz="0.000219"/>
    </inertial>
    <visual>
      <origin rpy="0 0 0" xyz="0 0 0"/>
      <geometry>
        <mesh filename="package://robotiq_ft_sensor/meshes/visual/robotiq_ft300.STL"/>
      </geometry>
      <material name="Robotiq-Black">
        <color rgba="0.2 0.2 0.2 1.0"/>
      </material>
    </visual>
    <collision>
      <!-- <origin xyz="0 0 0" rpy="0 0 0" /> -->
      <origin rpy="0 0 0" xyz="0 0 0.0175"/>
      <geometry>
        <cylinder length="0.035" radius="0.0375"/>
        <!-- <mesh filename="package://robotiq_ft_sensor/meshes/collision/robotiq_ft300.STL"/> -->
      </geometry>
    </collision>
  </link>
  <!-- Link representing the FT300 mounting plate -->
  <link name="ft300_mounting_plate">
    <visual>
      <origin rpy="0 0 0" xyz="0 0 0"/>
      <geometry>
        <mesh filename="package://robotiq_ft_sensor/meshes/visual/mountings/robotiq_ft300-G-062-COUPLING_G-50-4M6-1D6_20181119.STL"/>
      </geometry>
      <material name="Robotiq-Grey">
        <color rgba="0.4 0.4 0.4 1.0"/>
      </material>
    </visual>
    <collision>
      <!-- <origin xyz="0 0 0" rpy="0 0 0" /> -->
      <origin rpy="0 0 0" xyz="0 0 0.0065"/>
      <geometry>
        <cylinder length="0.013" radius="0.0375"/>
        <!-- <mesh filename="package://robotiq_ft_sensor/meshes/collision/mountings/robotiq_ft300-G-062-COUPLING_G-50-4M6-1D6_20181119.STL"/> -->
      </geometry>
    </collision>
  </link>
  <!-- Connect force sensor with mounting/coupling plate -->
  <joint name="ft300_mounting_plate_joint" type="fixed">
    <origin rpy="0 3.141592653589793 0" xyz="0 0 0.0415"/>
    <parent link="ft300_mounting_plate"/>
    <child link="ft300_sensor"/>
  </joint>
  <!-- FORCE REFERENCE FRAME _______________________________________________________________________________
            As specified in the documentation:
            - The Z axis passes through the center of the depression with positive direction in the tool direction.
            - The X axis traces a symmetric line centered on the connector; the positive direction
                points the opposite way away from the connector.
            - The Y axis uses the right hand thumb rule according to X-Z. -->
  <joint name="measurement_joint" type="fixed">
    <origin rpy="0 3.141592653589793 -1.5707963267948966" xyz="0 0 0"/>
    <parent link="ft300_sensor"/>
    <child link="robotiq_ft_frame_id"/>
  </joint>
  <link name="robotiq_ft_frame_id"/>
  <link name="robotiq_arg2f_base_link">
    <inertial>
      <origin rpy="0 0 0" xyz="8.625E-08 -4.6583E-06 0.03145"/>
      <mass value="0.22652"/>
      <inertia ixx="0.00020005" ixy="-4.2442E-10" ixz="-2.9069E-10" iyy="0.00017832" iyz="-3.4402E-08" izz="0.00013478"/>
    </inertial>
    <visual>
      <origin rpy="0 0 0" xyz="0 0 0"/>
      <geometry>
        <mesh filename="package://robotiq_2f_140_gripper_visualization/meshes/visual/robotiq_arg2f_base_link.stl"/>
      </geometry>
      <material name="">
        <color rgba="0.1 0.1 0.1 1"/>
      </material>
    </visual>
    <collision>
      <origin rpy="0 0 0" xyz="0 0 0"/>
      <geometry>
        <mesh filename="package://robotiq_2f_140_gripper_visualization/meshes/collision/robotiq_arg2f_base_link.stl"/>
      </geometry>
    </collision>
  </link>
  <link name="left_outer_knuckle">
    <inertial>
      <origin rpy="0 0 0" xyz="-0.000200000000003065 0.0199435877845359 0.0292245259211331"/>
      <mass value="0.00853198276973456"/>
      <inertia ixx="2.89328108496468E-06" ixy="-1.57935047237397E-19" ixz="-1.93980378593255E-19" iyy="1.86719750325683E-06" iyz="-1.21858577871576E-06" izz="1.21905238907251E-06"/>
    </inertial>
    <visual>
      <origin rpy="0 0 0" xyz="0 0 0"/>
      <geometry>
        <mesh filename="package://robotiq_2f_140_gripper_visualization/meshes/visual/robotiq_arg2f_140_outer_knuckle.stl"/>
      </geometry>
      <material name="">
        <color rgba="0.792156862745098 0.819607843137255 0.933333333333333 1"/>
      </material>
    </visual>
    <collision>
      <origin rpy="0 0 0" xyz="0 0 0"/>
      <geometry>
        <mesh filename="package://robotiq_2f_140_gripper_visualization/meshes/collision/robotiq_arg2f_140_outer_knuckle.stl"/>
      </geometry>
    </collision>
  </link>
  <link name="left_outer_finger">
    <inertial>
      <origin rpy="0 0 0" xyz="0.00030115855001899 0.0373907951953854 -0.0208027427000385"/>
      <mass value="0.022614240507152"/>
      <inertia ixx="1.52518312458174E-05" ixy="9.76583423954399E-10" ixz="-5.43838577022588E-10" iyy="6.17694243867776E-06" iyz="6.78636130740228E-06" izz="1.16494917907219E-05"/>
    </inertial>
    <visual>
      <origin rpy="0 0 0" xyz="0 0 0"/>
      <geometry>
        <mesh filename="package://robotiq_2f_140_gripper_visualization/meshes/visual/robotiq_arg2f_140_outer_finger.stl"/>
      </geometry>
      <material name="">
        <color rgba="0.1 0.1 0.1 1"/>
      </material>
    </visual>
    <collision>
      <origin rpy="0 0 0" xyz="0 0 0"/>
      <geometry>
        <mesh filename="package://robotiq_2f_140_gripper_visualization/meshes/collision/robotiq_arg2f_140_outer_finger.stl"/>
      </geometry>
    </collision>
  </link>
  <link name="left_inner_finger">
    <inertial>
      <origin rpy="0 0 0" xyz="0.000299999999999317 0.0160078233491243 -0.0136945669206257"/>
      <mass value="0.0104003125914103"/>
      <inertia ixx="2.71909453810972E-06" ixy="1.35402465472579E-21" ixz="-7.1817349065269E-22" iyy="7.69100314106116E-07" iyz="6.74715432769696E-07" izz="2.30315190420171E-06"/>
    </inertial>
    <visual>
      <origin rpy="0 0 0" xyz="0 0 0"/>
      <geometry>
        <mesh filename="package://robotiq_2f_140_gripper_visualization/meshes/visual/robotiq_arg2f_140_inner_finger.stl"/>
      </geometry>
      <material name="">
        <color rgba="0.1 0.1 0.1 1"/>
      </material>
    </visual>
    <collision>
      <origin rpy="0 0 0" xyz="0 0 0"/>
      <geometry>
        <mesh filename="package://robotiq_2f_140_gripper_visualization/meshes/collision/robotiq_arg2f_140_inner_finger.stl"/>
      </geometry>
    </collision>
  </link>
  <link name="left_inner_finger_pad">
    <visual>
      <origin rpy="0 0 0" xyz="0 0 0"/>
      <geometry>
        <box size="0.027 0.065 0.0075"/>
      </geometry>
      <material name="">
        <color rgba="0.9 0.9 0.9 1"/>
      </material>
    </visual>
    <collision>
      <origin rpy="0 0 0" xyz="0 0 0"/>
      <geometry>
        <box size="0.03 0.07 0.0075"/>
      </geometry>
      <material name="">
        <color rgba="0.9 0.0 0.0 1"/>
      </material>
    </collision>
  </link>
  <link name="left_inner_knuckle">
    <inertial>
      <origin rpy="0 0 0" xyz="0.000123011831763771 0.0507850843201817 0.00103968640075166"/>
      <mass value="0.0271177346495152"/>
      <inertia ixx="2.61910379223783E-05" ixy="-2.43616858946494E-07" ixz="-6.37789906117123E-09" iyy="2.8270243746167E-06" iyz="-5.37200748039765E-07" izz="2.83695868220296E-05"/>
    </inertial>
    <visual>
      <origin rpy="0 0 0" xyz="0 0 0"/>
      <geometry>
        <mesh filename="package://robotiq_2f_140_gripper_visualization/meshes/visual/robotiq_arg2f_140_inner_knuckle.stl"/>
      </geometry>
      <material name="">
        <color rgba="0.1 0.1 0.1 1"/>
      </material>
    </visual>
    <collision>
      <origin rpy="0 0 0" xyz="0 0 0"/>
      <geometry>
        <mesh filename="package://robotiq_2f_140_gripper_visualization/meshes/collision/robotiq_arg2f_140_inner_knuckle.stl"/>
      </geometry>
    </collision>
  </link>
  <link name="right_outer_knuckle">
    <inertial>
      <origin rpy="0 0 0" xyz="-0.000200000000003065 0.0199435877845359 0.0292245259211331"/>
      <mass value="0.00853198276973456"/>
      <inertia ixx="2.89328108496468E-06" ixy="-1.57935047237397E-19" ixz="-1.93980378593255E-19" iyy="1.86719750325683E-06" iyz="-1.21858577871576E-06" izz="1.21905238907251E-06"/>
    </inertial>
    <visual>
      <origin rpy="0 0 0" xyz="0 0 0"/>
      <geometry>
        <mesh filename="package://robotiq_2f_140_gripper_visualization/meshes/visual/robotiq_arg2f_140_outer_knuckle.stl"/>
      </geometry>
      <material name="">
        <color rgba="0.792156862745098 0.819607843137255 0.933333333333333 1"/>
      </material>
    </visual>
    <collision>
      <origin rpy="0 0 0" xyz="0 0 0"/>
      <geometry>
        <mesh filename="package://robotiq_2f_140_gripper_visualization/meshes/collision/robotiq_arg2f_140_outer_knuckle.stl"/>
      </geometry>
    </collision>
  </link>
  <link name="right_outer_finger">
    <inertial>
      <origin rpy="0 0 0" xyz="0.00030115855001899 0.0373907951953854 -0.0208027427000385"/>
      <mass value="0.022614240507152"/>
      <inertia ixx="1.52518312458174E-05" ixy="9.76583423954399E-10" ixz="-5.43838577022588E-10" iyy="6.17694243867776E-06" iyz="6.78636130740228E-06" izz="1.16494917907219E-05"/>
    </inertial>
    <visual>
      <origin rpy="0 0 0" xyz="0 0 0"/>
      <geometry>
        <mesh filename="package://robotiq_2f_140_gripper_visualization/meshes/visual/robotiq_arg2f_140_outer_finger.stl"/>
      </geometry>
      <material name="">
        <color rgba="0.1 0.1 0.1 1"/>
      </material>
    </visual>
    <collision>
      <origin rpy="0 0 0" xyz="0 0 0"/>
      <geometry>
        <mesh filename="package://robotiq_2f_140_gripper_visualization/meshes/collision/robotiq_arg2f_140_outer_finger.stl"/>
      </geometry>
    </collision>
  </link>
  <link name="right_inner_finger">
    <inertial>
      <origin rpy="0 0 0" xyz="0.000299999999999317 0.0160078233491243 -0.0136945669206257"/>
      <mass value="0.0104003125914103"/>
      <inertia ixx="2.71909453810972E-06" ixy="1.35402465472579E-21" ixz="-7.1817349065269E-22" iyy="7.69100314106116E-07" iyz="6.74715432769696E-07" izz="2.30315190420171E-06"/>
    </inertial>
    <visual>
      <origin rpy="0 0 0" xyz="0 0 0"/>
      <geometry>
        <mesh filename="package://robotiq_2f_140_gripper_visualization/meshes/visual/robotiq_arg2f_140_inner_finger.stl"/>
      </geometry>
      <material name="">
        <color rgba="0.1 0.1 0.1 1"/>
      </material>
    </visual>
    <collision>
      <origin rpy="0 0 0" xyz="0 0 0"/>
      <geometry>
        <mesh filename="package://robotiq_2f_140_gripper_visualization/meshes/collision/robotiq_arg2f_140_inner_finger.stl"/>
      </geometry>
    </collision>
  </link>
  <link name="right_inner_finger_pad">
    <visual>
      <origin rpy="0 0 0" xyz="0 0 0"/>
      <geometry>
        <box size="0.027 0.065 0.0075"/>
      </geometry>
      <material name="">
        <color rgba="0.9 0.9 0.9 1"/>
      </material>
    </visual>
    <collision>
      <origin rpy="0 0 0" xyz="0 0 0"/>
      <geometry>
        <box size="0.03 0.07 0.0075"/>
      </geometry>
      <material name="">
        <color rgba="0.9 0.0 0.0 1"/>
      </material>
    </collision>
  </link>
  <link name="right_inner_knuckle">
    <inertial>
      <origin rpy="0 0 0" xyz="0.000123011831763771 0.0507850843201817 0.00103968640075166"/>
      <mass value="0.0271177346495152"/>
      <inertia ixx="2.61910379223783E-05" ixy="-2.43616858946494E-07" ixz="-6.37789906117123E-09" iyy="2.8270243746167E-06" iyz="-5.37200748039765E-07" izz="2.83695868220296E-05"/>
    </inertial>
    <visual>
      <origin rpy="0 0 0" xyz="0 0 0"/>
      <geometry>
        <mesh filename="package://robotiq_2f_140_gripper_visualization/meshes/visual/robotiq_arg2f_140_inner_knuckle.stl"/>
      </geometry>
      <material name="">
        <color rgba="0.1 0.1 0.1 1"/>
      </material>
    </visual>
    <collision>
      <origin rpy="0 0 0" xyz="0 0 0"/>
      <geometry>
        <mesh filename="package://robotiq_2f_140_gripper_visualization/meshes/collision/robotiq_arg2f_140_inner_knuckle.stl"/>
      </geometry>
    </collision>
  </link>
  <joint name="finger_joint" type="revolute">
    <origin rpy="2.2957963267948966 0 0" xyz="0 -0.030601 0.054905"/>
    <parent link="robotiq_arg2f_base_link"/>
    <child link="left_outer_knuckle"/>
    <axis xyz="-1 0 0"/>
    <limit effort="1000" lower="0" upper="0.7" velocity="2.0"/>
  </joint>
  <joint name="left_outer_finger_joint" type="fixed">
    <origin rpy="0 0 0" xyz="0 0.01821998610742 0.0260018192872234"/>
    <parent link="left_outer_knuckle"/>
    <child link="left_outer_finger"/>
    <axis xyz="1 0 0"/>
  </joint>
  <joint name="left_inner_knuckle_joint" type="revolute">
    <origin rpy="2.2957963267948966 0 0.0" xyz="0 -0.0127 0.06142"/>
    <parent link="robotiq_arg2f_base_link"/>
    <child link="left_inner_knuckle"/>
    <axis xyz="1 0 0"/>
    <limit effort="1000" lower="-0.8757" upper="0.8757" velocity="2.0"/>
    <mimic joint="finger_joint" multiplier="-1" offset="0"/>
  </joint>
  <joint name="left_inner_finger_joint" type="revolute">
    <origin rpy="-0.725 0 0" xyz="0 0.0817554015893473 -0.0282203446692936"/>
    <parent link="left_outer_finger"/>
    <child link="left_inner_finger"/>
    <axis xyz="1 0 0"/>
    <limit effort="1000" lower="-0.8757" upper="0.8757" velocity="2.0"/>
    <mimic joint="finger_joint" multiplier="1" offset="0"/>
  </joint>
  <joint name="left_inner_finger_pad_joint" type="fixed">
    <origin rpy="0 0 0" xyz="0 0.0457554015893473 -0.0272203446692936"/>
    <parent link="left_inner_finger"/>
    <child link="left_inner_finger_pad"/>
    <axis xyz="0 0 1"/>
  </joint>
  <joint name="right_outer_knuckle_joint" type="revolute">
    <origin rpy="2.2957963267948966 0 3.141592653589793" xyz="0 0.030601 0.054905"/>
    <parent link="robotiq_arg2f_base_link"/>
    <child link="right_outer_knuckle"/>
    <axis xyz="1 0 0"/>
    <limit effort="1000" lower="-0.725" upper="0.725" velocity="2.0"/>
    <mimic joint="finger_joint" multiplier="-1" offset="0"/>
  </joint>
  <joint name="right_outer_finger_joint" type="fixed">
    <origin rpy="0 0 0" xyz="0 0.01821998610742 0.0260018192872234"/>
    <parent link="right_outer_knuckle"/>
    <child link="right_outer_finger"/>
    <axis xyz="1 0 0"/>
  </joint>
  <joint name="right_inner_knuckle_joint" type="revolute">
    <origin rpy="2.2957963267948966 0 -3.141592653589793" xyz="0 0.0127 0.06142"/>
    <parent link="robotiq_arg2f_base_link"/>
    <child link="right_inner_knuckle"/>
    <axis xyz="1 0 0"/>
    <limit effort="1000" lower="-0.8757" upper="0.8757" velocity="2.0"/>
    <mimic joint="finger_joint" multiplier="-1" offset="0"/>
  </joint>
  <joint name="right_inner_finger_joint" type="revolute">
    <origin rpy="-0.725 0 0" xyz="0 0.0817554015893473 -0.0282203446692936"/>
    <parent link="right_outer_finger"/>
    <child link="right_inner_finger"/>
    <axis xyz="1 0 0"/>
    <limit effort="1000" lower="-0.8757" upper="0.8757" velocity="2.0"/>
    <mimic joint="finger_joint" multiplier="1" offset="0"/>
  </joint>
  <joint name="right_inner_finger_pad_joint" type="fixed">
    <origin rpy="0 0 0" xyz="0 0.0457554015893473 -0.0272203446692936"/>
    <parent link="right_inner_finger"/>
    <child link="right_inner_finger_pad"/>
    <axis xyz="0 0 1"/>
  </joint>
  <transmission name="finger_joint_trans">
    <type>transmission_interface/SimpleTransmission</type>
    <joint name="finger_joint">
      <hardwareInterface>PositionJointInterface</hardwareInterface>
    </joint>
    <actuator name="finger_joint_motor">
      <mechanicalReduction>1</mechanicalReduction>
    </actuator>
  </transmission>
  <!-- Rotate frame forward for attaching gripper -->
  <link name="ft300_sensor_forward"/>
  <joint name="ft_attachment_point" type="fixed">
    <!-- <parent link="ft300_sensor"/> -->
    <parent link="robotiq_ft_frame_id"/>
    <child link="ft300_sensor_forward"/>
    <!-- <origin xyz="0 0 0" rpy="${pi} 0 0"/> -->
    <origin rpy="0 0 1.5707963267948966" xyz="0 0 0"/>
  </joint>
  <joint name="ft_to_gripper" type="fixed">
    <parent link="ft300_sensor_forward"/>
    <child link="robotiq_arg2f_base_link"/>
  </joint>
  <!-- Add collision object for cables (transforms and size approximate) -->
  <link name="robotiq_cable_collision_link">
    <collision>
      <origin rpy="1.5707963267948966 0 0" xyz="0 0.075 -0.035"/>
      <geometry>
        <cylinder length="0.1" radius="0.01"/>
      </geometry>
    </collision>
    <collision>
      <origin rpy="1.5707963267948966 0 0" xyz="0 0.075 0.02"/>
      <geometry>
        <cylinder length="0.1" radius="0.01"/>
      </geometry>
    </collision>
  </link>
  <joint name="ft300_to_robotiq_cable_collision_link" type="fixed">
    <parent link="ft300_sensor_forward"/>
    <child link="robotiq_cable_collision_link"/>
  </joint>
  <!-- Add end-effector link coinciding with j1n6s300_end_effector in same kinematic chain as ft300_sensor_forward -->
  <link name="end_effector"/>
  <joint name="gripper_to_end_effector" type="fixed">
    <origin xyz="0 0 0.197"/>
    <parent link="robotiq_arg2f_base_link"/>
    <child link="end_effector"/>
  </joint>
</robot>

